Workbook

Sheet 📊 Dashboard
B1: PORTEFEUILLE DE SERVICES SI — DSID
B3: Vue consolidée — Mis à jour automatiquement depuis les feuilles applicatives
B5: Total Applications | D5: Catalogue (production) | F5: Pipeline (conception) | H5: Criticité Critique | J5: Criticité Élevée / Haute
B8: =COUNTA(Inventaire!B2:B14) -> 13 | D8: =COUNTIF(Inventaire!I2:I14,"Catalogue") -> 8 | F8: =COUNTIF(Inventaire!I2:I14,"Pipeline") -> 5 | H8: =COUNTIF(Inventaire!K2:K14,"Critique") -> 7 | J8: =COUNTIF(Inventaire!K2:K14,"Élevée")+COUNTIF(Inventaire!K2:K14,"Haute") -> 1
B11: ID | C11: Application | D11: Catégorie | E11: Propriétaire | F11: Direction | G11: Statut Portfolio | H11: Criticité | I11: Hébergement | J11: Mode Dev | K11: Prestataire | L11: Dispo. Cible | M11: Données Sensibles
B12: =Inventaire!B2 -> APP-001 | C12: =Inventaire!C2 -> DocuTrace Lab | D12: =Inventaire!D2 -> Métier | E12: =Inventaire!P2 -> DSID | F12: =Inventaire!Q2 -> LNCM | G12: =Inventaire!I2 -> Catalogue | H12: =Inventaire!K2 -> Moyenne | I12: =Inventaire!M2 -> On-prem | J12: =Inventaire!F2 -> Interne | K12: =Inventaire!G2 -> - | L12: =Inventaire!R2 -> 99% | M12: ='📋 DocuTrace Lab'!C34 -> Non
B13: =Inventaire!B3 -> APP-002 | C13: =Inventaire!C3 -> VigiUp | D13: =Inventaire!D3 -> Métier | E13: =Inventaire!P3 -> DSID | F13: =Inventaire!Q3 -> Vigilance | G13: =Inventaire!I3 -> Catalogue | H13: =Inventaire!K3 -> Critique | I13: =Inventaire!M3 -> On-prem | J13: =Inventaire!F3 -> Interne | K13: =Inventaire!G3 -> - | L13: =Inventaire!R3 -> 99% | M13: ='📋 VigiUp'!C34 -> Non
B14: =Inventaire!B4 -> APP-004 | C14: =Inventaire!C4 -> Moussanada | D14: =Inventaire!D4 -> Support | E14: =Inventaire!P4 -> DSID | F14: =Inventaire!Q4 -> AMMPS | G14: =Inventaire!I4 -> Catalogue | H14: =Inventaire!K4 -> Moyenne | I14: =Inventaire!M4 -> On-prem | J14: =Inventaire!F4 -> Interne | K14: =Inventaire!G4 -> - | L14: =Inventaire!R4 -> 99% | M14: ='📋 Moussanada'!C34 -> -
B15: =Inventaire!B5 -> APP-005 | C15: =Inventaire!C5 -> Sentinel | D15: =Inventaire!D5 -> Métier | E15: =Inventaire!P5 -> AMMPS | F15: =Inventaire!Q5 -> Surveillance Post-Marketing | G15: =Inventaire!I5 -> Catalogue | H15: =Inventaire!K5 -> Critique | I15: =Inventaire!M5 -> On-prem | J15: =Inventaire!F5 -> Interne | K15: =Inventaire!G5 -> DSID | L15: =Inventaire!R5 -> 99% | M15: ='📋 Sentinel'!C34 -> Oui
B16: =Inventaire!B6 -> APP-006 | C16: =Inventaire!C6 -> E-Services | D16: =Inventaire!D6 -> Métier | E16: =Inventaire!P6 -> - | F16: =Inventaire!Q6 -> Dispositif Médical | G16: =Inventaire!I6 -> Catalogue | H16: =Inventaire!K6 -> Critique | I16: =Inventaire!M6 -> Cloud | J16: =Inventaire!F6 -> Prestataire | K16: =Inventaire!G6 -> Digital Performance | L16: =Inventaire!R6 -> 99% | M16: ='📋 E-Services'!C34 -> Oui
B17: =Inventaire!B7 -> APP-007 | C17: =Inventaire!C7 -> GIMPS | D17: =Inventaire!D7 -> Métier | E17: =Inventaire!P7 -> DMP | F17: =Inventaire!Q7 -> Réception, Finances, Évaluation, Inspection | G17: =Inventaire!I7 -> Catalogue | H17: =Inventaire!K7 -> Critique | I17: =Inventaire!M7 -> On-prem | J17: =Inventaire!F7 -> Prestataire | K17: =Inventaire!G7 -> Nevolys | L17: =Inventaire!R7 -> 99% | M17: ='📋 GIMPS'!C34 -> Oui
B18: =Inventaire!B8 -> APP-009 | C18: =Inventaire!C8 -> Attestation Échantillons Médicaux | D18: =Inventaire!D8 -> Métier | E18: =Inventaire!P8 -> - | F18: =Inventaire!Q8 -> - | G18: =Inventaire!I8 -> Catalogue | H18: =Inventaire!K8 -> Moyenne | I18: =Inventaire!M8 -> On-prem | J18: =Inventaire!F8 -> Prestataire | K18: =Inventaire!G8 -> Digital Performance | L18: =Inventaire!R8 -> 99% | M18: ='📋 Attestation Échantillons '!C34 -> Oui
B19: =Inventaire!B9 -> APP-014 | C19: =Inventaire!C9 -> e-RBI | D19: =Inventaire!D9 -> Métier | E19: =Inventaire!P9 -> - | F19: =Inventaire!Q9 -> - | G19: =Inventaire!I9 -> Pipeline | H19: =Inventaire!K9 -> Élevée | I19: =Inventaire!M9 -> On-prem | J19: =Inventaire!F9 -> Prestataire | K19: =Inventaire!G9 -> ONE TECHNOLOGY | L19: =Inventaire!R9 -> 99% | M19: ='📋 e-RBI'!C34 -> Oui
B20: =Inventaire!B10 -> APP-015 | C20: =Inventaire!C10 -> Tarkhiss | D20: =Inventaire!D10 -> Métier | E20: =Inventaire!P10 -> CDG Incept | F20: =Inventaire!Q10 -> AMMPS | G20: =Inventaire!I10 -> Catalogue | H20: =Inventaire!K10 -> Critique | I20: =Inventaire!M10 -> Cloud | J20: =Inventaire!F10 -> Prestataire | K20: =Inventaire!G10 -> CDG Incept / Ribatis | L20: =Inventaire!R10 -> 99% | M20: ='📋 Tarkhiss'!C34 -> Oui
B21: =Inventaire!B11 -> APP-016 | C21: =Inventaire!C11 -> Gestion de Délais | D21: =Inventaire!D11 -> Métier | E21: =Inventaire!P11 -> DSID | F21: =Inventaire!Q11 -> Pôle Inspection | G21: =Inventaire!I11 -> Pipeline | H21: =Inventaire!K11 -> Critique | I21: =Inventaire!M11 -> On-prem | J21: =Inventaire!F11 -> Interne | K21: =Inventaire!G11 -> - | L21: =Inventaire!R11 -> 99% | M21: ='📋 Gestion de Délais'!C34 -> Oui
B22: =Inventaire!B12 -> APP-017 | C22: =Inventaire!C12 -> MA Tracker | D22: =Inventaire!D12 -> Métier | E22: =Inventaire!P12 -> - | F22: =Inventaire!Q12 -> - | G22: =Inventaire!I12 -> Pipeline | H22: =Inventaire!K12 -> - | I22: =Inventaire!M12 -> On-prem | J22: =Inventaire!F12 -> Interne | K22: =Inventaire!G12 -> - | L22: =Inventaire!R12 -> 99% | M22: ='📋 MA Tracker'!C34 -> -
B23: =Inventaire!B13 -> APP-018 | C23: =Inventaire!C13 -> Intranet Qualité | D23: =Inventaire!D13 -> Métier | E23: =Inventaire!P13 -> DSID | F23: =Inventaire!Q13 -> Qualité | G23: =Inventaire!I13 -> Pipeline | H23: =Inventaire!K13 -> Moyenne | I23: =Inventaire!M13 -> Cloud | J23: =Inventaire!F13 -> Interne | K23: =Inventaire!G13 -> - | L23: =Inventaire!R13 -> 99% | M23: ='📋 Intranet Qualité'!C34 -> Non
B24: =Inventaire!B14 -> APP-019 | C24: =Inventaire!C14 -> LIMS LabVantage (Smart Lab) | D24: =Inventaire!D14 -> Métier | E24: =Inventaire!P14 -> - | F24: =Inventaire!Q14 -> LNCM | G24: =Inventaire!I14 -> Pipeline | H24: =Inventaire!K14 -> Critique | I24: =Inventaire!M14 -> On-prem | J24: =Inventaire!F14 -> Acquisition | K24: =Inventaire!G14 -> LabVantage Solutions | L24: =Inventaire!R14 -> 99% | M24: ='📋 LIMS LabVantage'!C34 -> Oui

Sheet Inventaire
B1: ID | C1: Nom de l'application | D1: Type | E1: Périmètre / Domaine | F1: Mode de développement | G1: Prestataire | H1: Date mise en production | I1: Statut Portfolio | J1: Statut | K1: Criticité | L1: Données traitées | M1: Hébergement | N1: Technologies principales | O1: Maintenance | P1: Propriétaire | Q1: Direction bénéficiaire | R1: Disponibilité | S1: RTO | T1: RPO
B2: APP-001 | C2: DocuTrace Lab | D2: ='📋 DocuTrace Lab'!C8 -> Métier | E2: Suivi des impressions et traçabilité des documents imprimés | F2: Interne | G2: ='📋 DocuTrace Lab'!C13 -> - | H2: 20/02/2026 | I2: ='📋 DocuTrace Lab'!C10 -> Catalogue | J2: En projet | K2: ='📋 DocuTrace Lab'!E8 -> Moyenne | L2: MySQL | M2: On-prem | N2: Python, FastAPI, React | P2: DSID | Q2: LNCM | R2: 99% | S2: 1 jour | T2: 1 jour
B3: APP-002 | C3: VigiUp | D3: ='📋 VigiUp'!C8 -> Métier | E3: Suivi des effets indésirables des produits de santé | F3: Interne | G3: ='📋 VigiUp'!C13 -> - | H3: 20/01/2026 | I3: ='📋 VigiUp'!C10 -> Catalogue | J3: En projet | K3: ='📋 VigiUp'!E8 -> Critique | L3: MySQL 8.0 | M3: On-prem | N3: Spring Boot 3.x, Java 17, React 18, TypeScript, MySQL 8.0 | P3: DSID | Q3: Vigilance | R3: 99% | S3: 1 jour | T3: 1 jour
B4: APP-004 | C4: Moussanada | D4: ='📋 Moussanada'!C8 -> Support | E4: Helpdesk IT — gestion des tickets incidents et demandes | F4: Interne | G4: ='📋 Moussanada'!C13 -> - | H4: 03/2026 | I4: ='📋 Moussanada'!C10 -> Catalogue | J4: En production | K4: ='📋 Moussanada'!E8 -> Moyenne | L4: - | M4: On-prem | N4: GLPi | O4: Aucune | P4: DSID | Q4: AMMPS | R4: 99% | S4: - | T4: -
B5: APP-005 | C5: Sentinel | D5: ='📋 Sentinel'!C8 -> Métier | E5: Signalement et gestion des problèmes liés aux médicaments sur le marché | F5: Interne | G5: ='📋 Sentinel'!C13 -> DSID | H5: 25/02/2026 | I5: ='📋 Sentinel'!C10 -> Catalogue | J5: En projet | K5: ='📋 Sentinel'!E8 -> Critique | L5: MySQL | M5: On-prem | N5: React, SpringBoot, MySQL | P5: AMMPS | Q5: Surveillance Post-Marketing | R5: 99% | S5: 1 jour | T5: 1 jour
B6: APP-006 | C6: E-Services | D6: ='📋 E-Services'!C8 -> Métier | E6: Gestion des demandes d'import, autorisation de fabrication locale, et négativité | F6: Prestataire | G6: ='📋 E-Services'!C13 -> Digital Performance | H6: Legacy | I6: ='📋 E-Services'!C10 -> Catalogue | J6: En production | K6: ='📋 E-Services'!E8 -> Critique | L6: MySQL | M6: Cloud | N6: PHP, jQuery, AJAX, MySQL | O6: Curative | P6: - | Q6: Dispositif Médical | R6: 99% | S6: 1 jour | T6: 72 heures
B7: APP-007 | C7: GIMPS | D7: ='📋 GIMPS'!C8 -> Métier | E7: Suivi et traitement des demandes d'autorisation des produits de santé | F7: Prestataire | G7: ='📋 GIMPS'!C13 -> Nevolys | H7: - | I7: ='📋 GIMPS'!C10 -> Catalogue | J7: En production | K7: ='📋 GIMPS'!E8 -> Critique | L7: Textuelle, PDF, img, SQL | M7: On-prem | N7: SQL Server, .NET | O7: Curative | P7: DMP | Q7: Réception, Finances, Évaluation, Inspection | R7: 99% | S7: 1 jour | T7: 72 heures
B8: APP-009 | C8: Attestation Échantillons Médicaux | D8: ='📋 Attestation Échantillons '!C8 -> Métier | E8: Gestion des attestations pour le port des échantillons médicaux | F8: Prestataire | G8: ='📋 Attestation Échantillons '!C13 -> Digital Performance | H8: - | I8: ='📋 Attestation Échantillons '!C10 -> Catalogue | J8: En production | K8: ='📋 Attestation Échantillons '!E8 -> Moyenne | L8: Données personnelles | M8: On-prem | N8: Apache v2.4.58, PHP v5.6.30, SQL Server, jQuery v1.11.3 | O8: Curative | P8: - | Q8: - | R8: 99% | S8: - | T8: -
B9: APP-014 | C9: e-RBI | D9: ='📋 e-RBI'!C8 -> Métier | E9: Demande d'autorisation de recherche biomédicale | F9: Prestataire | G9: ='📋 e-RBI'!C13 -> ONE TECHNOLOGY | H9: - | I9: ='📋 e-RBI'!C10 -> Pipeline | J9: En projet | K9: ='📋 e-RBI'!E8 -> Élevée | L9: Données confidentielles, données sensibles | M9: On-prem | N9: HammerJS, Typeahead.js, jQuery, Bootstrap 5, PHP, MySQL | P9: - | Q9: - | R9: 99% | S9: - | T9: -
B10: APP-015 | C10: Tarkhiss | D10: ='📋 Tarkhiss'!C8 -> Métier | E10: Gestion et suivi du processus d'octroi des autorisations pour les médicaments | F10: Prestataire | G10: ='📋 Tarkhiss'!C13 -> CDG Incept / Ribatis | H10: 02/2026 | I10: ='📋 Tarkhiss'!C10 -> Catalogue | J10: En Projet | K10: ='📋 Tarkhiss'!E8 -> Critique | L10: Données personnelles, sensibles, confidentielles | M10: Cloud | N10: Karaz framework, Java | P10: CDG Incept | Q10: AMMPS | R10: 99% | S10: - | T10: -
B11: APP-016 | C11: Gestion de Délais | D11: ='📋 Gestion de Délais'!C8 -> Métier | E11: Gestion des délais des attestations EPI | F11: Interne | G11: ='📋 Gestion de Délais'!C13 -> - | H11: 01/05/2026 | I11: ='📋 Gestion de Délais'!C10 -> Pipeline | J11: En projet | K11: ='📋 Gestion de Délais'!E8 -> Critique | L11: Dates d'arrivée et délivrance des dossiers | M11: On-prem | N11: Java 17, Spring Boot 3.3.0, Node.js, React 18, MySQL 8.4.3 | P11: DSID | Q11: Pôle Inspection | R11: 99% | S11: 24h | T11: 24h
B12: APP-017 | C12: MA Tracker | D12: ='📋 MA Tracker'!C8 -> Métier | E12: Gestion des délais des AMM (Autorisations de Mise sur le Marché) | F12: Interne | G12: ='📋 MA Tracker'!C13 -> - | H12: - | I12: ='📋 MA Tracker'!C10 -> Pipeline | J12: En production | K12: ='📋 MA Tracker'!E8 -> - | L12: - | M12: On-prem | N12: Python, Tkinter, SQLite | P12: - | Q12: - | R12: 99% | S12: - | T12: -
B13: APP-018 | C13: Intranet Qualité | D13: Métier | E13: Portail intranet dédié à la gestion de la qualité | F13: Interne | G13: ='📋 MA Tracker'!C13 -> - | H13: - | I13: ='📋 Intranet Qualité'!C10 -> Pipeline | J13: En projet | K13: Moyenne | L13: - | M13: Cloud | N13: SharePoint | O13: - | P13: DSID | Q13: Qualité | R13: 99% | S13: - | T13: -
B14: APP-019 | C14: LIMS LabVantage (Smart Lab) | D14: Métier | E14: Système LIMS pour la gestion des analyses et données de laboratoire | F14: Acquisition | G14: ='📋 LIMS LabVantage'!C13 -> LabVantage Solutions | H14: - | I14: ='📋 LIMS LabVantage'!C10 -> Pipeline | J14: En projet | K14: Critique | L14: Données confidentielles | M14: On-prem | N14: LabVantage LIMS, Java, Oracle DB | O14: - | P14: - | Q14: LNCM | R14: 99% | S14: - | T14: -

Sheet 📋 DocuTrace Lab
B1: APP-001 · DocuTrace Lab
B2: =_xlfn.CONCAT(B10,": ",C10) -> Statut Portfolio: Catalogue | C2: Criticité : Moyenne
B4: 1 · Identification du service
B5: ID Service | C5: APP-001
B6: Propriétaire | C6: DSID
B7: Direction bénéficiaire | C7: LNCM
B8: Catégorie | C8: Métier | E8: Moyenne
B9: Date de création | C9: 20/02/2026
B10: Statut Portfolio | C10: Catalogue
B11: Hébergement | C11: On-prem
B12: Mode de développement | C12: Interne
B13: Prestataire | C13: -
B15: 2 · Proposition de valeur
B16: Objectif du service | C16: Suivi des impressions et traçabilité des documents imprimés
B17: Problème métier résolu | C17: Suivi et traçabilité des documents imprimés
B18: Bénéfices attendus | C18: Facilité et sûreté de la traçabilité
B19: Parties prenantes | C19: DSID (Admin), LNCM (Évaluateurs, CS, CD, Tech PC + Bio)
B21: 3 · Description
B22: Description fonctionnelle | C22: Impression centralisée et gestion centralisée des documents
B23: Utilisateurs | C23: DSID (Administrateur), LNCM
B24: Processus supportés | C24: Processus de Saisie des Résultats des Analyses
B25: Fréquence d'utilisation | C25: Quotidien
B27: 4 · Architecture & dépendances
B28: Stack technologique | C28: Python, FastAPI, React
B29: Infrastructure | C29: Windows 11
B30: Données traitées | C30: MySQL
B31: Intégrations | C31: Sumatra, LibreOffice
B33: 5 · Sécurité & conformité
B34: Données sensibles | C34: Non
B35: Réglementation | C35: ISO 9001 / ISO 17025
B36: Classification sécurité | C36: Basse
B37: Journalisation | C37: Oui
B38: Sauvegarde | C38: Oui
B40: 6 · Performance & SLA
B41: Disponibilité cible | C41: 99%
B42: RTO | C42: 1 jour
B43: RPO | C43: 1 jour
B44: Support horaire | C44: Jours de travail
B46: 7 · Risques
B47: Risques principaux | C47: N/A
...

Sheet 📋 VigiUp
B1: APP-002 · VigiUp
B2: =_xlfn.CONCAT(B10,": ",C10) -> Statut Portfolio: Catalogue | C2: Criticité : Critique
B4: 1 · Identification du service
B5: ID Service | C5: APP-002
B6: Propriétaire | C6: DSID
B7: Direction bénéficiaire | C7: Vigilance
B8: Catégorie | C8: Métier | E8: Critique
B9: Date de création | C9: 20/01/2026
B10: Statut Portfolio | C10: Catalogue
B11: Hébergement | C11: On-prem
B12: Mode de développement | C12: Interne
B13: Prestataire | C13: -
B15: 2 · Proposition de valeur
B16: Objectif du service | C16: Suivi des effets indésirables des produits de santé
B17: Problème métier résolu | C17: Faciliter le suivi des effets indésirables
B18: Bénéfices attendus | C18: Rapidité et facilité de suivi
B19: Parties prenantes | C19: Vigilance
B21: 3 · Description
B22: Description fonctionnelle | C22: Suivi des effets indésirables des produits de santé
B23: Utilisateurs | C23: Service Vigilance, Citoyens
B24: Processus supportés | C24: -
B25: Fréquence d'utilisation | C25: Quotidienne
B27: 4 · Architecture & dépendances
B28: Stack technologique | C28: Spring Boot 3.x, Java 17, React 18, TypeScript, MySQL 8.0
B29: Infrastructure | C29: -
B30: Données traitées | C30: MySQL 8.0
B31: Intégrations | C31: -
B33: 5 · Sécurité & conformité
B34: Données sensibles | C34: Non
B35: Réglementation | C35: -
B36: Classification sécurité | C36: -
B37: Journalisation | C37: Oui
B38: Sauvegarde | C38: Oui
B40: 6 · Performance & SLA
B41: Disponibilité cible | C41: 0.99
B42: RTO | C42: 1 jour
B43: RPO | C43: 1 jour
B44: Support horaire | C44: Jours ouvrables
B46: 7 · Risques
B47: Risques principaux | C47: Bugs
...

Sheet 📋 Moussanada
B1: APP-004 · Moussanada
B2: =_xlfn.CONCAT(B10,": ",C10) -> Statut Portfolio: Catalogue | C2: Criticité : Moyenne
B4: 1 · Identification du service
B5: ID Service | C5: APP-004
B6: Propriétaire | C6: DSID
B7: Direction bénéficiaire | C7: AMMPS
B8: Catégorie | C8: Support | E8: Moyenne
B9: Date de création | C9: 03/2026
B10: Statut Portfolio | C10: Catalogue
B11: Hébergement | C11: On-prem
B12: Mode de développement | C12: Interne
B13: Prestataire | C13: -
B15: 2 · Proposition de valeur
B16: Objectif du service | C16: Helpdesk IT — gestion des tickets incidents et demandes
B17: Problème métier résolu | C17: Centraliser la gestion des incidents et demandes IT
B18: Bénéfices attendus | C18: Traçabilité complète et réactivité du support IT
B19: Parties prenantes | C19: DSID, AMMPS
B21: 3 · Description
B22: Description fonctionnelle | C22: Gestion et suivi des tickets via GLPI
B23: Utilisateurs | C23: DSID, Tous les utilisateurs AMMPS
B24: Processus supportés | C24: Support IT
B25: Fréquence d'utilisation | C25: Quotidienne
B27: 4 · Architecture & dépendances
B28: Stack technologique | C28: GLPi
B29: Infrastructure | C29: -
B30: Données traitées | C30: -
B31: Intégrations | C31: -
B33: 5 · Sécurité & conformité
B34: Données sensibles | C34: -
B35: Réglementation | C35: -
B36: Classification sécurité | C36: -
B37: Journalisation | C37: -
B38: Sauvegarde | C38: -
B40: 6 · Performance & SLA
B41: Disponibilité cible | C41: -
B42: RTO | C42: -
B43: RPO | C43: -
B44: Support horaire | C44: -
B46: 7 · Risques
B47: Risques principaux | C47: -
...

Sheet 📋 Sentinel
B1: APP-005 · Sentinel
B2: =_xlfn.CONCAT(B10,": ",C10) -> Statut Portfolio: Catalogue | C2: Criticité : Critique
B4: 1 · Identification du service
B5: ID Service | C5: APP-005
B6: Propriétaire | C6: AMMPS
B7: Direction bénéficiaire | C7: Surveillance Post-Marketing
B8: Catégorie | C8: Métier | E8: Critique
B9: Date de création | C9: 25/02/2026
B10: Statut Portfolio | C10: Catalogue
B11: Hébergement | C11: On-prem
B12: Mode de développement | C12: Interne
B13: Prestataire | C13: DSID
B15: 2 · Proposition de valeur
B16: Objectif du service | C16: Signalement et gestion des problèmes liés aux médicaments sur le marché
B17: Problème métier résolu | C17: Traçabilité des réclamations, reporting, gestion des droits et accès
B18: Bénéfices attendus | C18: Gain en productivité, sûreté de la base de données, facilité de gestion
B19: Parties prenantes | C19: Surveillance Post-Marketing, Inspection, Directeur Général
B21: 3 · Description
B22: Description fonctionnelle | C22: Suivi des défauts de qualité des médicaments avant consommation
B23: Utilisateurs | C23: DSID (Admin), Chef de Service, Évaluateurs, Clients
B24: Processus supportés | C24: Processus de Déclaration des défauts de qualité
B25: Fréquence d'utilisation | C25: Quotidienne
B27: 4 · Architecture & dépendances
B28: Stack technologique | C28: React, SpringBoot, MySQL
B29: Infrastructure | C29: Windows 11
B30: Données traitées | C30: MySQL
B31: Intégrations | C31: À renseigner
B33: 5 · Sécurité & conformité
B34: Données sensibles | C34: Oui
B35: Réglementation | C35: CNDP
B36: Classification sécurité | C36: Haute
B37: Journalisation | C37: Oui
B38: Sauvegarde | C38: Oui
B40: 6 · Performance & SLA
B41: Disponibilité cible | C41: 99%
B42: RTO | C42: 1 jour
B43: RPO | C43: 1 jour
B44: Support horaire | C44: Jours de travail
B46: 7 · Risques
B47: Risques principaux | C47: N/A
...

Sheet 📋 E-Services
B1: APP-006 · E-Services
B2: =_xlfn.CONCAT(B10,": ",C10) -> Statut Portfolio: Catalogue | C2: Criticité : Critique
B4: 1 · Identification du service
B5: ID Service | C5: APP-006
B6: Propriétaire | C6: -
B7: Direction bénéficiaire | C7: Dispositif Médical
B8: Catégorie | C8: Métier | E8: Critique
B9: Date de création | C9: Legacy
B10: Statut Portfolio | C10: Catalogue
B11: Hébergement | C11: Cloud
B12: Mode de développement | C12: Prestataire
B13: Prestataire | C13: Digital Performance
B15: 2 · Proposition de valeur
B16: Objectif du service | C16: Gestion des demandes d'import, autorisation de fabrication locale, et négativité
B17: Problème métier résolu | C17: Traçabilité BDD, facilité de remplissage clients, reporting, gestion des droits
B18: Bénéfices attendus | C18: Gain en productivité, cohérence BDD, sécurité renforcée, gestion des réclamations
B19: Parties prenantes | C19: Dispositif Médical
B21: 3 · Description
B22: Description fonctionnelle | C22: Gestion des demandes d'import, fabrication locale et négativité
B23: Utilisateurs | C23: Évaluateurs, Clients, Administrateur (DSID)
B24: Processus supportés | C24: Demande d'import, autorisation fabrication locale et négativité
B25: Fréquence d'utilisation | C25: Quotidienne
B27: 4 · Architecture & dépendances
B28: Stack technologique | C28: PHP, jQuery, AJAX, MySQL
B29: Infrastructure | C29: XAMP Apache
B30: Données traitées | C30: MySQL
B31: Intégrations | C31: BD sur Site
B33: 5 · Sécurité & conformité
B34: Données sensibles | C34: Oui
B35: Réglementation | C35: CNDP
B36: Classification sécurité | C36: Haute
B37: Journalisation | C37: Oui
B38: Sauvegarde | C38: Oui
B40: 6 · Performance & SLA
B41: Disponibilité cible | C41: 99%
B42: RTO | C42: 1 jour
B43: RPO | C43: 72 heures
B44: Support horaire | C44: Jours de travail
B46: 7 · Risques
B47: Risques principaux | C47: N/A
...

Sheet 📋 GIMPS
B1: APP-007 · GIMPS
B2: =_xlfn.CONCAT(B10,": ",C10) -> Statut Portfolio: Catalogue | C2: Criticité : Critique
B4: 1 · Identification du service
B5: ID Service | C5: APP-007
B6: Propriétaire | C6: DMP
B7: Direction bénéficiaire | C7: Réception, Finances, Évaluation, Inspection
B8: Catégorie | C8: Métier | E8: Critique
B9: Date de création | C9: -
B10: Statut Portfolio | C10: Catalogue
B11: Hébergement | C11: On-prem
B12: Mode de développement | C12: Prestataire
B13: Prestataire | C13: Nevolys
B15: 2 · Proposition de valeur
B16: Objectif du service | C16: Suivi et traitement des demandes d'autorisation des produits de santé
B17: Problème métier résolu | C17: Digitaliser la gestion des circuits de traitement de l'agence
B18: Bénéfices attendus | C18: Centraliser et digitaliser les circuits de travail
B19: Parties prenantes | C19: DSID, Réception, Finances, Évaluation, Inspection
B21: 3 · Description
B22: Description fonctionnelle | C22: Suivi et traitement des demandes d'autorisation des produits de santé
B23: Utilisateurs | C23: Administrateur, Chef de Service, Évaluateur, Agent de Saisie
B24: Processus supportés | C24: Réception, Finances, Inspection et Évaluation
B25: Fréquence d'utilisation | C25: Quotidienne
B27: 4 · Architecture & dépendances
B28: Stack technologique | C28: SQL Server, .NET
B29: Infrastructure | C29: Windows Server 2016 Standard v1607
B30: Données traitées | C30: Textuelle, PDF, img, SQL
B31: Intégrations | C31: -
B33: 5 · Sécurité & conformité
B34: Données sensibles | C34: Oui
B35: Réglementation | C35: -
B36: Classification sécurité | C36: Critique
B37: Journalisation | C37: Oui
B38: Sauvegarde | C38: Oui
B40: 6 · Performance & SLA
B41: Disponibilité cible | C41: 0.99
B42: RTO | C42: 1 jour
B43: RPO | C43: 72 heures
B44: Support horaire | C44: Jours de travail
B46: 7 · Risques
B47: Risques principaux | C47: Technologie dépréciée
...

Sheet 📋 Attestation Échantillons 
B1: APP-009 · Attestation Échantillons Médicaux
B2: =_xlfn.CONCAT(B10,": ",C10) -> Statut Portfolio: Catalogue | C2: Criticité : Moyenne
B4: 1 · Identification du service
B5: ID Service | C5: APP-009
B6: Propriétaire | C6: -
B7: Direction bénéficiaire | C7: -
B8: Catégorie | C8: Métier | E8: Moyenne
B9: Date de création | C9: -
B10: Statut Portfolio | C10: Catalogue
B11: Hébergement | C11: On-prem
B12: Mode de développement | C12: Prestataire
B13: Prestataire | C13: Digital Performance
B15: 2 · Proposition de valeur
B16: Objectif du service | C16: Gestion des attestations pour le port des échantillons médicaux
B17: Problème métier résolu | C17: -
B18: Bénéfices attendus | C18: -
B19: Parties prenantes | C19: -
B21: 3 · Description
B22: Description fonctionnelle | C22: Gestion des attestations pour le port des échantillons médicaux
B23: Utilisateurs | C23: -
B24: Processus supportés | C24: -
B25: Fréquence d'utilisation | C25: -
B27: 4 · Architecture & dépendances
B28: Stack technologique | C28: Apache v2.4.58, PHP v5.6.30, SQL Server, jQuery v1.11.3
B29: Infrastructure | C29: -
B30: Données traitées | C30: Données personnelles
B31: Intégrations | C31: -
B33: 5 · Sécurité & conformité
B34: Données sensibles | C34: Oui
B35: Réglementation | C35: -
B36: Classification sécurité | C36: -
B37: Journalisation | C37: Oui
B38: Sauvegarde | C38: Oui
B40: 6 · Performance & SLA
B41: Disponibilité cible | C41: -
B42: RTO | C42: -
B43: RPO | C43: -
B44: Support horaire | C44: -
B46: 7 · Risques
B47: Risques principaux | C47: -
...

Sheet 📋 e-RBI
B1: APP-014 · e-RBI
B2: =_xlfn.CONCAT(B10,": ",C10) -> Statut Portfolio: Pipeline | C2: Criticité : Élevée
B4: 1 · Identification du service
B5: ID Service | C5: APP-014
B6: Propriétaire | C6: -
B7: Direction bénéficiaire | C7: -
B8: Catégorie | C8: Métier | E8: Élevée
B9: Date de création | C9: -
B10: Statut Portfolio | C10: Pipeline
B11: Hébergement | C11: On-prem
B12: Mode de développement | C12: Prestataire
B13: Prestataire | C13: ONE TECHNOLOGY
B15: 2 · Proposition de valeur
B16: Objectif du service | C16: Demande d'autorisation de recherche biomédicale
B17: Problème métier résolu | C17: -
B18: Bénéfices attendus | C18: -
B19: Parties prenantes | C19: -
B21: 3 · Description
B22: Description fonctionnelle | C22: Demande d'autorisation de recherche biomédicale pour médicaments expérimentaux
B23: Utilisateurs | C23: -
B24: Processus supportés | C24: Recherche biomédicale
B25: Fréquence d'utilisation | C25: -
B27: 4 · Architecture & dépendances
B28: Stack technologique | C28: HammerJS, Typeahead.js, jQuery, Bootstrap 5, PHP, MySQL
B29: Infrastructure | C29: -
B30: Données traitées | C30: Données confidentielles, données sensibles
B31: Intégrations | C31: -
B33: 5 · Sécurité & conformité
B34: Données sensibles | C34: Oui
B35: Réglementation | C35: -
B36: Classification sécurité | C36: -
B37: Journalisation | C37: -
B38: Sauvegarde | C38: -
B40: 6 · Performance & SLA
B41: Disponibilité cible | C41: -
B42: RTO | C42: -
B43: RPO | C43: -
B44: Support horaire | C44: -
B46: 7 · Risques
B47: Risques principaux | C47: -
...

Sheet 📋 Tarkhiss
B1: APP-015 · Tarkhiss
B2: =_xlfn.CONCAT(B10,": ",C10) -> Statut Portfolio: Catalogue | C2: Criticité : Critique
B4: 1 · Identification du service
B5: ID Service | C5: APP-015
B6: Propriétaire | C6: CDG Incept
B7: Direction bénéficiaire | C7: AMMPS
B8: Catégorie | C8: Métier | E8: Critique
B9: Date de création | C9: 02/2026
B10: Statut Portfolio | C10: Catalogue
B11: Hébergement | C11: Cloud
B12: Mode de développement | C12: Prestataire
B13: Prestataire | C13: CDG Incept / Ribatis
B15: 2 · Proposition de valeur
B16: Objectif du service | C16: Gestion et suivi du processus d'octroi des autorisations pour les médicaments
B17: Problème métier résolu | C17: -
B18: Bénéfices attendus | C18: -
B19: Parties prenantes | C19: -
B21: 3 · Description
B22: Description fonctionnelle | C22: Demande et suivi des autorisations pour les EPI (Établissements Pharmaceutiques et Industriels)
B23: Utilisateurs | C23: -
B24: Processus supportés | C24: -
B25: Fréquence d'utilisation | C25: -
B27: 4 · Architecture & dépendances
B28: Stack technologique | C28: Karaz framework, Java
B29: Infrastructure | C29: -
B30: Données traitées | C30: Données personnelles, sensibles, confidentielles
B31: Intégrations | C31: -
B33: 5 · Sécurité & conformité
B34: Données sensibles | C34: Oui
B35: Réglementation | C35: -
B36: Classification sécurité | C36: -
B37: Journalisation | C37: Oui
B38: Sauvegarde | C38: Oui
B40: 6 · Performance & SLA
B41: Disponibilité cible | C41: -
B42: RTO | C42: -
B43: RPO | C43: -
B44: Support horaire | C44: -
B46: 7 · Risques
B47: Risques principaux | C47: -
...

Sheet 📋 Gestion de Délais
B1: APP-016 · Gestion de Délais
B2: =_xlfn.CONCAT(B10,": ",C10) -> Statut Portfolio: Pipeline | C2: Criticité : Critique
B4: 1 · Identification du service
B5: ID Service | C5: APP-016
B6: Propriétaire | C6: DSID
B7: Direction bénéficiaire | C7: Pôle Inspection
B8: Catégorie | C8: Métier | E8: Critique
B9: Date de création | C9: 01/05/2026
B10: Statut Portfolio | C10: Pipeline
B11: Hébergement | C11: On-prem
B12: Mode de développement | C12: Interne
B13: Prestataire | C13: -
B15: 2 · Proposition de valeur
B16: Objectif du service | C16: Gestion des délais des attestations EPI
B17: Problème métier résolu | C17: Éviter les retards et dépassements de délai
B18: Bénéfices attendus | C18: Être toujours dans les délais
B19: Parties prenantes | C19: DSID, Inspection
B21: 3 · Description
B22: Description fonctionnelle | C22: Assurer le suivi des délais des dossiers fournis à l'AMMPS
B23: Utilisateurs | C23: Pôle Inspection
B24: Processus supportés | C24: Respect et suivi des délais légaux
B25: Fréquence d'utilisation | C25: Quotidien
B27: 4 · Architecture & dépendances
B28: Stack technologique | C28: Java 17, Spring Boot 3.3.0, Node.js, React 18, MySQL 8.4.3
B29: Infrastructure | C29: -
B30: Données traitées | C30: Dates d'arrivée et délivrance des dossiers
B31: Intégrations | C31: -
B33: 5 · Sécurité & conformité
B34: Données sensibles | C34: Oui
B35: Réglementation | C35: CNDP
B36: Classification sécurité | C36: -
B37: Journalisation | C37: Oui
B38: Sauvegarde | C38: Oui
B40: 6 · Performance & SLA
B41: Disponibilité cible | C41: 0.99
B42: RTO | C42: 24h
B43: RPO | C43: 24h
B44: Support horaire | C44: Jours ouvrés
B46: 7 · Risques
B47: Risques principaux | C47: Délai non comptabilisé correctement
...

Sheet 📋 MA Tracker
B1: APP-017 · MA Tracker
B2: =_xlfn.CONCAT(B10,": ",C10) -> Statut Portfolio: Pipeline | C2: Criticité : -
B4: 1 · Identification du service
B5: ID Service | C5: APP-017
B6: Propriétaire | C6: -
B7: Direction bénéficiaire | C7: -
B8: Catégorie | C8: Métier | E8: -
B9: Date de création | C9: -
B10: Statut Portfolio | C10: Pipeline
B11: Hébergement | C11: On-prem
B12: Mode de développement | C12: Interne
B13: Prestataire | C13: -
B15: 2 · Proposition de valeur
B16: Objectif du service | C16: Gestion des délais des AMM (Autorisations de Mise sur le Marché)
B17: Problème métier résolu | C17: -
B18: Bénéfices attendus | C18: -
B19: Parties prenantes | C19: -
B21: 3 · Description
B22: Description fonctionnelle | C22: Suivi et gestion des délais liés aux AMM
B23: Utilisateurs | C23: -
B24: Processus supportés | C24: -
B25: Fréquence d'utilisation | C25: -
B27: 4 · Architecture & dépendances
B28: Stack technologique | C28: Python, Tkinter, SQLite
B29: Infrastructure | C29: -
B30: Données traitées | C30: -
B31: Intégrations | C31: -
B33: 5 · Sécurité & conformité
B34: Données sensibles | C34: -
B35: Réglementation | C35: -
B36: Classification sécurité | C36: -
B37: Journalisation | C37: -
B38: Sauvegarde | C38: -
B40: 6 · Performance & SLA
B41: Disponibilité cible | C41: -
B42: RTO | C42: -
B43: RPO | C43: -
B44: Support horaire | C44: -
B46: 7 · Risques
B47: Risques principaux | C47: -
...

Sheet 📋 Intranet Qualité
B1: APP-018 · Intranet Qualité
B2: =_xlfn.CONCAT(B10,": ",C10) -> Statut Portfolio: Pipeline | C2: Criticité : Moyenne
B4: 1 · Identification du service
B5: ID Service | C5: APP-018
B6: Propriétaire | C6: DSID
B7: Direction bénéficiaire | C7: Qualité
B8: Catégorie | C8: Métier | E8: Moyenne
B9: Date de création | C9: -
B10: Statut Portfolio | C10: Pipeline
B11: Hébergement | C11: Cloud
B12: Mode de développement | C12: Interne
B13: Prestataire | C13: -
B15: 2 · Proposition de valeur
B16: Objectif du service | C16: Portail intranet dédié à la gestion de la qualité
B17: Problème métier résolu | C17: Centraliser la documentation et les processus qualité
B18: Bénéfices attendus | C18: Accessibilité et traçabilité documentaire
B19: Parties prenantes | C19: DSID, Service Qualité
B21: 3 · Description
B22: Description fonctionnelle | C22: Portail intranet de gestion documentaire qualité
B23: Utilisateurs | C23: Personnel AMMPS
B24: Processus supportés | C24: Management de la Qualité
B25: Fréquence d'utilisation | C25: Quotidien
B27: 4 · Architecture & dépendances
B28: Stack technologique | C28: SharePoint
B29: Infrastructure | C29: Microsoft 365
B30: Données traitées | C30: -
B31: Intégrations | C31: Microsoft 365
B33: 5 · Sécurité & conformité
B34: Données sensibles | C34: Non
B35: Réglementation | C35: ISO 9001 / ISO 17025
B36: Classification sécurité | C36: Moyenne
B37: Journalisation | C37: -
B38: Sauvegarde | C38: -
B40: 6 · Performance & SLA
B41: Disponibilité cible | C41: -
B42: RTO | C42: -
B43: RPO | C43: -
B44: Support horaire | C44: -
B46: 7 · Risques
B47: Risques principaux | C47: -
...

Sheet 📋 LIMS LabVantage
B1: APP-019 · LIMS LabVantage (Smart Lab)
B2: =_xlfn.CONCAT(B10,": ",C10) -> Statut Portfolio: Pipeline | C2: Criticité : Critique
B4: 1 · Identification du service
B5: ID Service | C5: APP-019
B6: Propriétaire | C6: -
B7: Direction bénéficiaire | C7: LNCM
B8: Catégorie | C8: Métier | E8: Critique
B9: Date de création | C9: -
B10: Statut Portfolio | C10: Pipeline
B11: Hébergement | C11: On-prem
B12: Mode de développement | C12: Acquisition
B13: Prestataire | C13: LabVantage Solutions
B15: 2 · Proposition de valeur
B16: Objectif du service | C16: Système LIMS pour la gestion des analyses et données de laboratoire
B17: Problème métier résolu | C17: Centraliser et automatiser la gestion des données analytiques du laboratoire
B18: Bénéfices attendus | C18: Traçabilité complète, conformité réglementaire, gain de productivité
B19: Parties prenantes | C19: LNCM, DSID
B21: 3 · Description
B22: Description fonctionnelle | C22: Gestion intégrée des échantillons, analyses, résultats et instruments de laboratoire
B23: Utilisateurs | C23: Techniciens et responsables de laboratoire
B24: Processus supportés | C24: Analyses de laboratoire
B25: Fréquence d'utilisation | C25: Quotidien
B27: 4 · Architecture & dépendances
B28: Stack technologique | C28: LabVantage LIMS, Java, Oracle DB
B29: Infrastructure | C29: Serveur dédié
B30: Données traitées | C30: Données confidentielles
B31: Intégrations | C31: -
B33: 5 · Sécurité & conformité
B34: Données sensibles | C34: Oui
B35: Réglementation | C35: ISO 17025
B36: Classification sécurité | C36: Haute
B37: Journalisation | C37: Oui
B38: Sauvegarde | C38: Oui
B40: 6 · Performance & SLA
B41: Disponibilité cible | C41: -
B42: RTO | C42: -
B43: RPO | C43: -
B44: Support horaire | C44: -
B46: 7 · Risques
B47: Risques principaux | C47: -
...

Sheet 🗺️ Légende
B1: LÉGENDE & RÉFÉRENTIELS
B3: STATUT PORTFOLIO | C3: Description
B4: Pipeline | C4: Service en conception / développement
B5: Catalogue | C5: Service en production active
B6: Retraité | C6: Service retiré du portefeuille
B8: CRITICITÉ | C8: Description
B9: Critique | C9: Impact majeur — arrêt total possible
B10: Haute / Élevée | C10: Impact important sur les opérations
B11: Moyenne | C11: Impact modéré
B12: Faible | C12: Impact minimal
B14: STATUT PRODUCTION | C14: Description
B15: En production | C15: Déployé et utilisé
B16: En projet | C16: En cours de développement / déploiement
... B21: Non | C21: Pas de données sensibles
